<robot name = "robot">
    <link name="0">
        <inertial>
            <origin xyz="0 0 2" rpy="0 0 0"/>
            <mass value="1" />
            <inertia ixx="100" ixy="0" ixz="0" iyy="100" iyz="0" izz="100" />
        </inertial>
        <visual>
            <origin xyz="0 0 2" rpy="0 0 0"/>
            <geometry>
                <box size="0.6226971482523986 0.8393749862805282 0.7866690631371045" />
            </geometry>
            <material name="Cyan">
                <color rgba="0 1.0 1.0 1.0"/>
            </material>
        </visual>
        <collision>
            <origin xyz="0 0 2" rpy="0 0 0"/>
            <geometry>
                <box size="0.6226971482523986 0.8393749862805282 0.7866690631371045" />
            </geometry>
        </collision>
    </link>
    <joint name="0_1" type="revolute">
       <parent link="0"/>
       <child  link="1"/>
       <origin rpy="0 0 0" xyz="-0.3113485741261993 0 2" />
     <axis xyz="0 1 0"/>
       <limit effort="0.0" lower="-3.14159" upper="3.14159" velocity="0.0"/>
    </joint>
    <link name="1">
        <inertial>
            <origin xyz="-0.2686827441169044 0 0" rpy="0 0 0"/>
            <mass value="1" />
            <inertia ixx="100" ixy="0" ixz="0" iyy="100" iyz="0" izz="100" />
        </inertial>
        <visual>
            <origin xyz="-0.2686827441169044 0 0" rpy="0 0 0"/>
            <geometry>
                <box size="0.5373654882338088 0.9714915273767168 0.7101137113835942" />
            </geometry>
            <material name="Cyan">
                <color rgba="0 1.0 1.0 1.0"/>
            </material>
        </visual>
        <collision>
            <origin xyz="-0.2686827441169044 0 0" rpy="0 0 0"/>
            <geometry>
                <box size="0.5373654882338088 0.9714915273767168 0.7101137113835942" />
            </geometry>
        </collision>
    </link>
    <joint name="1_2" type="revolute">
       <parent link="1"/>
       <child  link="2"/>
       <origin rpy="0 0 0" xyz="-0.2686827441169044 0 -0.3550568556917971" />
     <axis xyz="1 0 0"/>
       <limit effort="0.0" lower="-3.14159" upper="3.14159" velocity="0.0"/>
    </joint>
    <link name="2">
        <inertial>
            <origin xyz="0 0 -0.2728806180212722" rpy="0 0 0"/>
            <mass value="1" />
            <inertia ixx="100" ixy="0" ixz="0" iyy="100" iyz="0" izz="100" />
        </inertial>
        <visual>
            <origin xyz="0 0 -0.2728806180212722" rpy="0 0 0"/>
            <geometry>
                <box size="0.4376154040550936 0.4519822516459756 0.5457612360425445" />
            </geometry>
            <material name="Green">
                <color rgba="0.5 1 0.5 1.0"/>
            </material>
        </visual>
        <collision>
            <origin xyz="0 0 -0.2728806180212722" rpy="0 0 0"/>
            <geometry>
                <box size="0.4376154040550936 0.4519822516459756 0.5457612360425445" />
            </geometry>
        </collision>
    </link>
    <joint name="1_3" type="revolute">
       <parent link="1"/>
       <child  link="3"/>
       <origin rpy="0 0 0" xyz="-0.2686827441169044 0 0.3550568556917971" />
     <axis xyz="0 0 1"/>
       <limit effort="0.0" lower="-3.14159" upper="3.14159" velocity="0.0"/>
    </joint>
    <link name="3">
        <inertial>
            <origin xyz="0 0 0.3435076438707148" rpy="0 0 0"/>
            <mass value="1" />
            <inertia ixx="100" ixy="0" ixz="0" iyy="100" iyz="0" izz="100" />
        </inertial>
        <visual>
            <origin xyz="0 0 0.3435076438707148" rpy="0 0 0"/>
            <geometry>
                <box size="0.5317021123802037 0.5398169719545853 0.6870152877414296" />
            </geometry>
            <material name="Green">
                <color rgba="0.5 1 0.5 1.0"/>
            </material>
        </visual>
        <collision>
            <origin xyz="0 0 0.3435076438707148" rpy="0 0 0"/>
            <geometry>
                <box size="0.5317021123802037 0.5398169719545853 0.6870152877414296" />
            </geometry>
        </collision>
    </link>
    <joint name="2_4" type="revolute">
       <parent link="2"/>
       <child  link="4"/>
       <origin rpy="0 0 0" xyz="0 0.2259911258229878 -0.2728806180212722" />
     <axis xyz="0 1 0"/>
       <limit effort="0.0" lower="-3.14159" upper="3.14159" velocity="0.0"/>
    </joint>
    <link name="4">
        <inertial>
            <origin xyz="0 0.26865384678827575 0" rpy="0 0 0"/>
            <mass value="1" />
            <inertia ixx="100" ixy="0" ixz="0" iyy="100" iyz="0" izz="100" />
        </inertial>
        <visual>
            <origin xyz="0 0.26865384678827575 0" rpy="0 0 0"/>
            <geometry>
                <box size="0.39913194534764 0.5373076935765515 0.36052808151476773" />
            </geometry>
            <material name="Green">
                <color rgba="0.5 1 0.5 1.0"/>
            </material>
        </visual>
        <collision>
            <origin xyz="0 0.26865384678827575 0" rpy="0 0 0"/>
            <geometry>
                <box size="0.39913194534764 0.5373076935765515 0.36052808151476773" />
            </geometry>
        </collision>
    </link>
    <joint name="2_5" type="revolute">
       <parent link="2"/>
       <child  link="5"/>
       <origin rpy="0 0 0" xyz="0 0 -0.5457612360425445" />
     <axis xyz="0 0 1"/>
       <limit effort="0.0" lower="-3.14159" upper="3.14159" velocity="0.0"/>
    </joint>
    <link name="5">
        <inertial>
            <origin xyz="0 0 -0.2968148498572397" rpy="0 0 0"/>
            <mass value="1" />
            <inertia ixx="100" ixy="0" ixz="0" iyy="100" iyz="0" izz="100" />
        </inertial>
        <visual>
            <origin xyz="0 0 -0.2968148498572397" rpy="0 0 0"/>
            <geometry>
                <box size="0.5947978005172063 0.569072517714698 0.5936296997144794" />
            </geometry>
            <material name="Cyan">
                <color rgba="0 1.0 1.0 1.0"/>
            </material>
        </visual>
        <collision>
            <origin xyz="0 0 -0.2968148498572397" rpy="0 0 0"/>
            <geometry>
                <box size="0.5947978005172063 0.569072517714698 0.5936296997144794" />
            </geometry>
        </collision>
    </link>
    <joint name="3_6" type="revolute">
       <parent link="3"/>
       <child  link="6"/>
       <origin rpy="0 0 0" xyz="0 0.26990848597729267 0.3435076438707148" />
     <axis xyz="0 1 0"/>
       <limit effort="0.0" lower="-3.14159" upper="3.14159" velocity="0.0"/>
    </joint>
    <link name="6">
        <inertial>
            <origin xyz="0 0.16563133413931022 0" rpy="0 0 0"/>
            <mass value="1" />
            <inertia ixx="100" ixy="0" ixz="0" iyy="100" iyz="0" izz="100" />
        </inertial>
        <visual>
            <origin xyz="0 0.16563133413931022 0" rpy="0 0 0"/>
            <geometry>
                <box size="0.3257562601637994 0.33126266827862044 0.43409531435564913" />
            </geometry>
            <material name="Cyan">
                <color rgba="0 1.0 1.0 1.0"/>
            </material>
        </visual>
        <collision>
            <origin xyz="0 0.16563133413931022 0" rpy="0 0 0"/>
            <geometry>
                <box size="0.3257562601637994 0.33126266827862044 0.43409531435564913" />
            </geometry>
        </collision>
    </link>
</robot>