<robot name = "robot">
    <link name="Torso">
        <inertial>
            <origin xyz="0 0 1.8" rpy="0 0 0"/>
            <mass value="1" />
            <inertia ixx="100" ixy="0" ixz="0" iyy="100" iyz="0" izz="100" />
        </inertial>
        <visual>
            <origin xyz="0 0 1.8" rpy="0 0 0"/>
            <geometry>
                <box size="0.5 0.8 1" />
            </geometry>
            <material name="Cyan">
                <color rgba="0 1.0 1.0 1.0"/>
            </material>
        </visual>
        <collision>
            <origin xyz="0 0 1.8" rpy="0 0 0"/>
            <geometry>
                <box size="0.5 0.8 1" />
            </geometry>
        </collision>
    </link>
    <joint name="Torso_LThigh" type="revolute">
       <parent link="Torso"/>
       <child  link="LThigh"/>
       <origin rpy="0 0 0" xyz="0 -0.35 1.3" />
     <axis xyz="0 1 0"/>
       <limit effort="0.0" lower="-3.14159" upper="3.14159" velocity="0.0"/>
    </joint>
    <link name="LThigh">
        <inertial>
            <origin xyz="0 0 -0.3" rpy="0 0 0"/>
            <mass value="1" />
            <inertia ixx="100" ixy="0" ixz="0" iyy="100" iyz="0" izz="100" />
        </inertial>
        <visual>
            <origin xyz="0 0 -0.3" rpy="0 0 0"/>
            <geometry>
                <box size="0.3 0.3 0.6" />
            </geometry>
            <material name="Cyan">
                <color rgba="0 1.0 1.0 1.0"/>
            </material>
        </visual>
        <collision>
            <origin xyz="0 0 -0.3" rpy="0 0 0"/>
            <geometry>
                <box size="0.3 0.3 0.6" />
            </geometry>
        </collision>
    </link>
    <joint name="LThigh_LShank" type="revolute">
       <parent link="LThigh"/>
       <child  link="LShank"/>
       <origin rpy="0 0 0" xyz="0 0 -0.6" />
     <axis xyz="0 1 0"/>
       <limit effort="0.0" lower="-3.14159" upper="3.14159" velocity="0.0"/>
    </joint>
    <link name="LShank">
        <inertial>
            <origin xyz="0 0 -0.35" rpy="0 0 0"/>
            <mass value="1" />
            <inertia ixx="100" ixy="0" ixz="0" iyy="100" iyz="0" izz="100" />
        </inertial>
        <visual>
            <origin xyz="0 0 -0.35" rpy="0 0 0"/>
            <geometry>
                <box size="0.3 0.3 0.7" />
            </geometry>
            <material name="Cyan">
                <color rgba="0 1.0 1.0 1.0"/>
            </material>
        </visual>
        <collision>
            <origin xyz="0 0 -0.35" rpy="0 0 0"/>
            <geometry>
                <box size="0.3 0.3 0.7" />
            </geometry>
        </collision>
    </link>
    <joint name="Torso_RThigh" type="revolute">
       <parent link="Torso"/>
       <child  link="RThigh"/>
       <origin rpy="0 0 0" xyz="0 0.35 1.3" />
     <axis xyz="0 1 0"/>
       <limit effort="0.0" lower="-3.14159" upper="3.14159" velocity="0.0"/>
    </joint>
    <link name="RThigh">
        <inertial>
            <origin xyz="0 0 -0.3" rpy="0 0 0"/>
            <mass value="1" />
            <inertia ixx="100" ixy="0" ixz="0" iyy="100" iyz="0" izz="100" />
        </inertial>
        <visual>
            <origin xyz="0 0 -0.3" rpy="0 0 0"/>
            <geometry>
                <box size="0.3 0.3 0.6" />
            </geometry>
            <material name="Cyan">
                <color rgba="0 1.0 1.0 1.0"/>
            </material>
        </visual>
        <collision>
            <origin xyz="0 0 -0.3" rpy="0 0 0"/>
            <geometry>
                <box size="0.3 0.3 0.6" />
            </geometry>
        </collision>
    </link>
    <joint name="RThigh_RShank" type="revolute">
       <parent link="RThigh"/>
       <child  link="RShank"/>
       <origin rpy="0 0 0" xyz="0 0 -0.6" />
     <axis xyz="0 1 0"/>
       <limit effort="0.0" lower="-3.14159" upper="3.14159" velocity="0.0"/>
    </joint>
    <link name="RShank">
        <inertial>
            <origin xyz="0 0 -0.35" rpy="0 0 0"/>
            <mass value="1" />
            <inertia ixx="100" ixy="0" ixz="0" iyy="100" iyz="0" izz="100" />
        </inertial>
        <visual>
            <origin xyz="0 0 -0.35" rpy="0 0 0"/>
            <geometry>
                <box size="0.3 0.3 0.7" />
            </geometry>
            <material name="Cyan">
                <color rgba="0 1.0 1.0 1.0"/>
            </material>
        </visual>
        <collision>
            <origin xyz="0 0 -0.35" rpy="0 0 0"/>
            <geometry>
                <box size="0.3 0.3 0.7" />
            </geometry>
        </collision>
    </link>
    <joint name="Torso_LArm" type="revolute">
       <parent link="Torso"/>
       <child  link="LArm"/>
       <origin rpy="0 0 0" xyz="0 -0.4 2.15" />
     <axis xyz="0 1 0"/>
       <limit effort="0.0" lower="-3.14159" upper="3.14159" velocity="0.0"/>
    </joint>
    <link name="LArm">
        <inertial>
            <origin xyz="0 -0.15 -0.4" rpy="0 0 0"/>
            <mass value="1" />
            <inertia ixx="100" ixy="0" ixz="0" iyy="100" iyz="0" izz="100" />
        </inertial>
        <visual>
            <origin xyz="0 -0.15 -0.4" rpy="0 0 0"/>
            <geometry>
                <box size="0.3 0.3 0.8" />
            </geometry>
            <material name="Cyan">
                <color rgba="0 1.0 1.0 1.0"/>
            </material>
        </visual>
        <collision>
            <origin xyz="0 -0.15 -0.4" rpy="0 0 0"/>
            <geometry>
                <box size="0.3 0.3 0.8" />
            </geometry>
        </collision>
    </link>
    <joint name="Torso_RArm" type="revolute">
       <parent link="Torso"/>
       <child  link="RArm"/>
       <origin rpy="0 0 0" xyz="0 0.4 2.15" />
     <axis xyz="0 1 0"/>
       <limit effort="0.0" lower="-3.14159" upper="3.14159" velocity="0.0"/>
    </joint>
    <link name="RArm">
        <inertial>
            <origin xyz="0 0.15 -0.4" rpy="0 0 0"/>
            <mass value="1" />
            <inertia ixx="100" ixy="0" ixz="0" iyy="100" iyz="0" izz="100" />
        </inertial>
        <visual>
            <origin xyz="0 0.15 -0.4" rpy="0 0 0"/>
            <geometry>
                <box size="0.3 0.3 0.8" />
            </geometry>
            <material name="Cyan">
                <color rgba="0 1.0 1.0 1.0"/>
            </material>
        </visual>
        <collision>
            <origin xyz="0 0.15 -0.4" rpy="0 0 0"/>
            <geometry>
                <box size="0.3 0.3 0.8" />
            </geometry>
        </collision>
    </link>
</robot>