<robot name = "robot">
    <link name="0">
        <inertial>
            <origin xyz="0 0 0.39929034043165323" rpy="0 0 0"/>
            <mass value="1" />
            <inertia ixx="100" ixy="0" ixz="0" iyy="100" iyz="0" izz="100" />
        </inertial>
        <visual>
            <origin xyz="0 0 0.39929034043165323" rpy="0 0 0"/>
            <geometry>
                <box size="0.8310207124655022 0.775709870044087 0.7985806808633067" />
            </geometry>
            <material name="Green">
                <color rgba="0.5 1 0.5 1.0"/>
            </material>
        </visual>
        <collision>
            <origin xyz="0 0 0.39929034043165323" rpy="0 0 0"/>
            <geometry>
                <box size="0.8310207124655022 0.775709870044087 0.7985806808633067" />
            </geometry>
        </collision>
    </link>
    <joint name="0_1" type="revolute">
       <parent link="0"/>
       <child  link="1"/>
       <origin rpy="0 0 0" xyz="0 0 0.7985806808633066" />
     <axis xyz="1 0 0"/>
       <limit effort="0.0" lower="-3.14159" upper="3.14159" velocity="0.0"/>
    </joint>
    <link name="1">
        <inertial>
            <origin xyz="0 0 0.33002252158171796" rpy="0 0 0"/>
            <mass value="1" />
            <inertia ixx="100" ixy="0" ixz="0" iyy="100" iyz="0" izz="100" />
        </inertial>
        <visual>
            <origin xyz="0 0 0.33002252158171796" rpy="0 0 0"/>
            <geometry>
                <box size="0.6281668983803264 0.534651709709616 0.6600450431634359" />
            </geometry>
            <material name="Cyan">
                <color rgba="0 1.0 1.0 1.0"/>
            </material>
        </visual>
        <collision>
            <origin xyz="0 0 0.33002252158171796" rpy="0 0 0"/>
            <geometry>
                <box size="0.6281668983803264 0.534651709709616 0.6600450431634359" />
            </geometry>
        </collision>
    </link>
    <joint name="1_2" type="revolute">
       <parent link="1"/>
       <child  link="2"/>
       <origin rpy="0 0 0" xyz="0 0 0.6600450431634359" />
     <axis xyz="1 0 0"/>
       <limit effort="0.0" lower="-3.14159" upper="3.14159" velocity="0.0"/>
    </joint>
    <link name="2">
        <inertial>
            <origin xyz="0 0 0.2920020399919642" rpy="0 0 0"/>
            <mass value="1" />
            <inertia ixx="100" ixy="0" ixz="0" iyy="100" iyz="0" izz="100" />
        </inertial>
        <visual>
            <origin xyz="0 0 0.2920020399919642" rpy="0 0 0"/>
            <geometry>
                <box size="0.5244249085679514 0.43740446894820795 0.5840040799839284" />
            </geometry>
            <material name="Cyan">
                <color rgba="0 1.0 1.0 1.0"/>
            </material>
        </visual>
        <collision>
            <origin xyz="0 0 0.2920020399919642" rpy="0 0 0"/>
            <geometry>
                <box size="0.5244249085679514 0.43740446894820795 0.5840040799839284" />
            </geometry>
        </collision>
    </link>
    <joint name="1_3" type="revolute">
       <parent link="1"/>
       <child  link="3"/>
       <origin rpy="0 0 0" xyz="-0.3140834491901632 0 0.33002252158171796" />
     <axis xyz="0 1 0"/>
       <limit effort="0.0" lower="-3.14159" upper="3.14159" velocity="0.0"/>
    </joint>
    <link name="3">
        <inertial>
            <origin xyz="-0.36873693687687376 0 0" rpy="0 0 0"/>
            <mass value="1" />
            <inertia ixx="100" ixy="0" ixz="0" iyy="100" iyz="0" izz="100" />
        </inertial>
        <visual>
            <origin xyz="-0.36873693687687376 0 0" rpy="0 0 0"/>
            <geometry>
                <box size="0.7374738737537475 0.48556649131358476 0.6386425262234978" />
            </geometry>
            <material name="Green">
                <color rgba="0.5 1 0.5 1.0"/>
            </material>
        </visual>
        <collision>
            <origin xyz="-0.36873693687687376 0 0" rpy="0 0 0"/>
            <geometry>
                <box size="0.7374738737537475 0.48556649131358476 0.6386425262234978" />
            </geometry>
        </collision>
    </link>
    <joint name="2_4" type="revolute">
       <parent link="2"/>
       <child  link="4"/>
       <origin rpy="0 0 0" xyz="-0.2622124542839757 0 0.2920020399919642" />
     <axis xyz="1 0 0"/>
       <limit effort="0.0" lower="-3.14159" upper="3.14159" velocity="0.0"/>
    </joint>
    <link name="4">
        <inertial>
            <origin xyz="-0.20413527494054093 0 0" rpy="0 0 0"/>
            <mass value="1" />
            <inertia ixx="100" ixy="0" ixz="0" iyy="100" iyz="0" izz="100" />
        </inertial>
        <visual>
            <origin xyz="-0.20413527494054093 0 0" rpy="0 0 0"/>
            <geometry>
                <box size="0.40827054988108186 0.40144232770729044 0.3144726878042345" />
            </geometry>
            <material name="Green">
                <color rgba="0.5 1 0.5 1.0"/>
            </material>
        </visual>
        <collision>
            <origin xyz="-0.20413527494054093 0 0" rpy="0 0 0"/>
            <geometry>
                <box size="0.40827054988108186 0.40144232770729044 0.3144726878042345" />
            </geometry>
        </collision>
    </link>
    <joint name="2_5" type="revolute">
       <parent link="2"/>
       <child  link="5"/>
       <origin rpy="0 0 0" xyz="0 0.21870223447410397 0.2920020399919642" />
     <axis xyz="1 0 0"/>
       <limit effort="0.0" lower="-3.14159" upper="3.14159" velocity="0.0"/>
    </joint>
    <link name="5">
        <inertial>
            <origin xyz="0 0.2666580485415593 0" rpy="0 0 0"/>
            <mass value="1" />
            <inertia ixx="100" ixy="0" ixz="0" iyy="100" iyz="0" izz="100" />
        </inertial>
        <visual>
            <origin xyz="0 0.2666580485415593 0" rpy="0 0 0"/>
            <geometry>
                <box size="0.5655852574639666 0.5333160970831186 0.4872828491712265" />
            </geometry>
            <material name="Cyan">
                <color rgba="0 1.0 1.0 1.0"/>
            </material>
        </visual>
        <collision>
            <origin xyz="0 0.2666580485415593 0" rpy="0 0 0"/>
            <geometry>
                <box size="0.5655852574639666 0.5333160970831186 0.4872828491712265" />
            </geometry>
        </collision>
    </link>
    <joint name="3_6" type="revolute">
       <parent link="3"/>
       <child  link="6"/>
       <origin rpy="0 0 0" xyz="-0.36873693687687376 0.24278324565679238 0" />
     <axis xyz="1 0 0"/>
       <limit effort="0.0" lower="-3.14159" upper="3.14159" velocity="0.0"/>
    </joint>
    <link name="6">
        <inertial>
            <origin xyz="0 0.18062217551079549 0" rpy="0 0 0"/>
            <mass value="1" />
            <inertia ixx="100" ixy="0" ixz="0" iyy="100" iyz="0" izz="100" />
        </inertial>
        <visual>
            <origin xyz="0 0.18062217551079549 0" rpy="0 0 0"/>
            <geometry>
                <box size="0.37134554820245763 0.36124435102159097 0.4221932387250404" />
            </geometry>
            <material name="Green">
                <color rgba="0.5 1 0.5 1.0"/>
            </material>
        </visual>
        <collision>
            <origin xyz="0 0.18062217551079549 0" rpy="0 0 0"/>
            <geometry>
                <box size="0.37134554820245763 0.36124435102159097 0.4221932387250404" />
            </geometry>
        </collision>
    </link>
    <joint name="3_7" type="revolute">
       <parent link="3"/>
       <child  link="7"/>
       <origin rpy="0 0 0" xyz="-0.7374738737537475 0 0" />
     <axis xyz="0 0 1"/>
       <limit effort="0.0" lower="-3.14159" upper="3.14159" velocity="0.0"/>
    </joint>
    <link name="7">
        <inertial>
            <origin xyz="-0.15689446340041238 0 0" rpy="0 0 0"/>
            <mass value="1" />
            <inertia ixx="100" ixy="0" ixz="0" iyy="100" iyz="0" izz="100" />
        </inertial>
        <visual>
            <origin xyz="-0.15689446340041238 0 0" rpy="0 0 0"/>
            <geometry>
                <box size="0.31378892680082476 0.39727823600294004 0.5077307938565234" />
            </geometry>
            <material name="Green">
                <color rgba="0.5 1 0.5 1.0"/>
            </material>
        </visual>
        <collision>
            <origin xyz="-0.15689446340041238 0 0" rpy="0 0 0"/>
            <geometry>
                <box size="0.31378892680082476 0.39727823600294004 0.5077307938565234" />
            </geometry>
        </collision>
    </link>
</robot>