<robot name = "robot">
    <link name="0">
        <inertial>
            <origin xyz="0 0 2.1043760898439383" rpy="0 0 0"/>
            <mass value="1" />
            <inertia ixx="100" ixy="0" ixz="0" iyy="100" iyz="0" izz="100" />
        </inertial>
        <visual>
            <origin xyz="0 0 2.1043760898439383" rpy="0 0 0"/>
            <geometry>
                <box size="0.7415034463190857 0.761265453075824 0.6135107263817239" />
            </geometry>
            <material name="Cyan">
                <color rgba="0 1.0 1.0 1.0"/>
            </material>
        </visual>
        <collision>
            <origin xyz="0 0 2.1043760898439383" rpy="0 0 0"/>
            <geometry>
                <box size="0.7415034463190857 0.761265453075824 0.6135107263817239" />
            </geometry>
        </collision>
    </link>
    <joint name="0_1" type="revolute">
       <parent link="0"/>
       <child  link="1"/>
       <origin rpy="0 0 0" xyz="0 0 1.7976207266530764" />
     <axis xyz="0 1 0"/>
       <limit effort="0.0" lower="-3.14159" upper="3.14159" velocity="0.0"/>
    </joint>
    <link name="1">
        <inertial>
            <origin xyz="0 0 -0.3095472404349284" rpy="0 0 0"/>
            <mass value="1" />
            <inertia ixx="100" ixy="0" ixz="0" iyy="100" iyz="0" izz="100" />
        </inertial>
        <visual>
            <origin xyz="0 0 -0.3095472404349284" rpy="0 0 0"/>
            <geometry>
                <box size="0.5887770770480955 0.9934444596594165 0.6190944808698567" />
            </geometry>
            <material name="Green">
                <color rgba="0.5 1 0.5 1.0"/>
            </material>
        </visual>
        <collision>
            <origin xyz="0 0 -0.3095472404349284" rpy="0 0 0"/>
            <geometry>
                <box size="0.5887770770480955 0.9934444596594165 0.6190944808698567" />
            </geometry>
        </collision>
    </link>
    <joint name="1_2" type="revolute">
       <parent link="1"/>
       <child  link="2"/>
       <origin rpy="0 0 0" xyz="0 0 -0.6190944808698567" />
     <axis xyz="1 0 0"/>
       <limit effort="0.0" lower="-3.14159" upper="3.14159" velocity="0.0"/>
    </joint>
    <link name="2">
        <inertial>
            <origin xyz="0 0 -0.36795811270735324" rpy="0 0 0"/>
            <mass value="1" />
            <inertia ixx="100" ixy="0" ixz="0" iyy="100" iyz="0" izz="100" />
        </inertial>
        <visual>
            <origin xyz="0 0 -0.36795811270735324" rpy="0 0 0"/>
            <geometry>
                <box size="0.5048053190841352 0.5484988888864805 0.7359162254147065" />
            </geometry>
            <material name="Cyan">
                <color rgba="0 1.0 1.0 1.0"/>
            </material>
        </visual>
        <collision>
            <origin xyz="0 0 -0.36795811270735324" rpy="0 0 0"/>
            <geometry>
                <box size="0.5048053190841352 0.5484988888864805 0.7359162254147065" />
            </geometry>
        </collision>
    </link>
    <joint name="1_3" type="revolute">
       <parent link="1"/>
       <child  link="3"/>
       <origin rpy="0 0 0" xyz="-0.2943885385240477 0 -0.3095472404349284" />
     <axis xyz="0 0 1"/>
       <limit effort="0.0" lower="-3.14159" upper="3.14159" velocity="0.0"/>
    </joint>
    <link name="3">
        <inertial>
            <origin xyz="-0.34694749903211924 0 0" rpy="0 0 0"/>
            <mass value="1" />
            <inertia ixx="100" ixy="0" ixz="0" iyy="100" iyz="0" izz="100" />
        </inertial>
        <visual>
            <origin xyz="-0.34694749903211924 0 0" rpy="0 0 0"/>
            <geometry>
                <box size="0.6938949980642385 0.5376747879353826 0.4223323160491571" />
            </geometry>
            <material name="Cyan">
                <color rgba="0 1.0 1.0 1.0"/>
            </material>
        </visual>
        <collision>
            <origin xyz="-0.34694749903211924 0 0" rpy="0 0 0"/>
            <geometry>
                <box size="0.6938949980642385 0.5376747879353826 0.4223323160491571" />
            </geometry>
        </collision>
    </link>
    <joint name="2_4" type="revolute">
       <parent link="2"/>
       <child  link="4"/>
       <origin rpy="0 0 0" xyz="0 0 -0.7359162254147065" />
     <axis xyz="1 0 0"/>
       <limit effort="0.0" lower="-3.14159" upper="3.14159" velocity="0.0"/>
    </joint>
    <link name="4">
        <inertial>
            <origin xyz="0 0 -0.22130501018425666" rpy="0 0 0"/>
            <mass value="1" />
            <inertia ixx="100" ixy="0" ixz="0" iyy="100" iyz="0" izz="100" />
        </inertial>
        <visual>
            <origin xyz="0 0 -0.22130501018425666" rpy="0 0 0"/>
            <geometry>
                <box size="0.47792960638966725 0.3893174197532561 0.4426100203685133" />
            </geometry>
            <material name="Green">
                <color rgba="0.5 1 0.5 1.0"/>
            </material>
        </visual>
        <collision>
            <origin xyz="0 0 -0.22130501018425666" rpy="0 0 0"/>
            <geometry>
                <box size="0.47792960638966725 0.3893174197532561 0.4426100203685133" />
            </geometry>
        </collision>
    </link>
    <joint name="2_5" type="revolute">
       <parent link="2"/>
       <child  link="5"/>
       <origin rpy="0 0 0" xyz="0.2524026595420676 0 -0.36795811270735324" />
     <axis xyz="0 0 1"/>
       <limit effort="0.0" lower="-3.14159" upper="3.14159" velocity="0.0"/>
    </joint>
    <link name="5">
        <inertial>
            <origin xyz="0.20332677394460721 0 0" rpy="0 0 0"/>
            <mass value="1" />
            <inertia ixx="100" ixy="0" ixz="0" iyy="100" iyz="0" izz="100" />
        </inertial>
        <visual>
            <origin xyz="0.20332677394460721 0 0" rpy="0 0 0"/>
            <geometry>
                <box size="0.40665354788921443 0.5136647362449402 0.4307483733394217" />
            </geometry>
            <material name="Cyan">
                <color rgba="0 1.0 1.0 1.0"/>
            </material>
        </visual>
        <collision>
            <origin xyz="0.20332677394460721 0 0" rpy="0 0 0"/>
            <geometry>
                <box size="0.40665354788921443 0.5136647362449402 0.4307483733394217" />
            </geometry>
        </collision>
    </link>
</robot>