<robot name = "robot">
    <link name="0">
        <inertial>
            <origin xyz="0 0 0.45613188775574054" rpy="0 0 0"/>
            <mass value="1" />
            <inertia ixx="100" ixy="0" ixz="0" iyy="100" iyz="0" izz="100" />
        </inertial>
        <visual>
            <origin xyz="0 0 0.45613188775574054" rpy="0 0 0"/>
            <geometry>
                <box size="0.8385123805586061 0.9190751625606246 0.9122637755114813" />
            </geometry>
            <material name="Green">
                <color rgba="0.5 1 0.5 1.0"/>
            </material>
        </visual>
        <collision>
            <origin xyz="0 0 0.45613188775574054" rpy="0 0 0"/>
            <geometry>
                <box size="0.8385123805586061 0.9190751625606246 0.9122637755114813" />
            </geometry>
        </collision>
    </link>
    <joint name="0_1" type="revolute">
       <parent link="0"/>
       <child  link="1"/>
       <origin rpy="0 0 0" xyz="0 0 0.9122637755114812" />
     <axis xyz="0 1 0"/>
       <limit effort="0.0" lower="-3.14159" upper="3.14159" velocity="0.0"/>
    </joint>
    <link name="1">
        <inertial>
            <origin xyz="0 0 0.4812865224991836" rpy="0 0 0"/>
            <mass value="1" />
            <inertia ixx="100" ixy="0" ixz="0" iyy="100" iyz="0" izz="100" />
        </inertial>
        <visual>
            <origin xyz="0 0 0.4812865224991836" rpy="0 0 0"/>
            <geometry>
                <box size="0.9386747903383168 0.8575693802965388 0.9625730449983672" />
            </geometry>
            <material name="Green">
                <color rgba="0.5 1 0.5 1.0"/>
            </material>
        </visual>
        <collision>
            <origin xyz="0 0 0.4812865224991836" rpy="0 0 0"/>
            <geometry>
                <box size="0.9386747903383168 0.8575693802965388 0.9625730449983672" />
            </geometry>
        </collision>
    </link>
    <joint name="1_2" type="revolute">
       <parent link="1"/>
       <child  link="2"/>
       <origin rpy="0 0 0" xyz="0 0.4287846901482694 0.4812865224991836" />
     <axis xyz="1 0 0"/>
       <limit effort="0.0" lower="-3.14159" upper="3.14159" velocity="0.0"/>
    </joint>
    <link name="2">
        <inertial>
            <origin xyz="0 0.3437909543204589 0" rpy="0 0 0"/>
            <mass value="1" />
            <inertia ixx="100" ixy="0" ixz="0" iyy="100" iyz="0" izz="100" />
        </inertial>
        <visual>
            <origin xyz="0 0.3437909543204589 0" rpy="0 0 0"/>
            <geometry>
                <box size="0.5086256364089458 0.6875819086409178 0.6813314798713" />
            </geometry>
            <material name="Green">
                <color rgba="0.5 1 0.5 1.0"/>
            </material>
        </visual>
        <collision>
            <origin xyz="0 0.3437909543204589 0" rpy="0 0 0"/>
            <geometry>
                <box size="0.5086256364089458 0.6875819086409178 0.6813314798713" />
            </geometry>
        </collision>
    </link>
    <joint name="1_3" type="revolute">
       <parent link="1"/>
       <child  link="3"/>
       <origin rpy="0 0 0" xyz="-0.4693373951691584 0 0.4812865224991836" />
     <axis xyz="1 0 0"/>
       <limit effort="0.0" lower="-3.14159" upper="3.14159" velocity="0.0"/>
    </joint>
    <link name="3">
        <inertial>
            <origin xyz="-0.3228221301760728 0 0" rpy="0 0 0"/>
            <mass value="1" />
            <inertia ixx="100" ixy="0" ixz="0" iyy="100" iyz="0" izz="100" />
        </inertial>
        <visual>
            <origin xyz="-0.3228221301760728 0 0" rpy="0 0 0"/>
            <geometry>
                <box size="0.6456442603521456 0.5694952617729264 0.6585144449014363" />
            </geometry>
            <material name="Cyan">
                <color rgba="0 1.0 1.0 1.0"/>
            </material>
        </visual>
        <collision>
            <origin xyz="-0.3228221301760728 0 0" rpy="0 0 0"/>
            <geometry>
                <box size="0.6456442603521456 0.5694952617729264 0.6585144449014363" />
            </geometry>
        </collision>
    </link>
    <joint name="2_4" type="revolute">
       <parent link="2"/>
       <child  link="4"/>
       <origin rpy="0 0 0" xyz="-0.2543128182044729 0.3437909543204589 0" />
     <axis xyz="1 0 0"/>
       <limit effort="0.0" lower="-3.14159" upper="3.14159" velocity="0.0"/>
    </joint>
    <link name="4">
        <inertial>
            <origin xyz="-0.22679535589898484 0 0" rpy="0 0 0"/>
            <mass value="1" />
            <inertia ixx="100" ixy="0" ixz="0" iyy="100" iyz="0" izz="100" />
        </inertial>
        <visual>
            <origin xyz="-0.22679535589898484 0 0" rpy="0 0 0"/>
            <geometry>
                <box size="0.45359071179796967 0.4734531909553716 0.5466278389552386" />
            </geometry>
            <material name="Green">
                <color rgba="0.5 1 0.5 1.0"/>
            </material>
        </visual>
        <collision>
            <origin xyz="-0.22679535589898484 0 0" rpy="0 0 0"/>
            <geometry>
                <box size="0.45359071179796967 0.4734531909553716 0.5466278389552386" />
            </geometry>
        </collision>
    </link>
</robot>